<?xml version="1.0"?>
<robot xmlns:xacro="http://www.ros.org/wiki/xacro" name="firefighter">
	
<xacro:property name="width" value=".2" />

  <link name="base">
    <visual>
      <geometry>
        <mesh filename="mycobot_pro_600/base.stl"/>
        
      </geometry>
      <material name="light_blue">
        <color rgba="0.678 0.847 0.902 1"/>
      </material>
      <origin xyz="0 0 0" rpy="0 0 0"/>
    </visual>
    <collision>
      <geometry>
        <mesh filename="mycobot_pro_600\link5.stl/base.stl"/>
      </geometry>
      <origin xyz="0 0 0" rpy="0 0 0"/>
    </collision>
    
    <inertial>
      <mass value="0.0"/>
      <origin xyz="0 0 0"/>
      <inertia ixx="0.1" iyy="0.1" izz="0.1" ixy="0.0" ixz="0.0" iyz="0.0"/>
    </inertial>
  </link>

  <link name="link1">
    <visual>
      <geometry>
        <mesh filename="mycobot_pro_600\link1.stl"/>
      </geometry>
      <material name="light_blue">
        <color rgba="0.678 0.847 0.902 1"/>
      </material>
      <origin xyz="0 0 0" rpy="0 0 3.1415926"/>
    </visual>
    <collision>
      <geometry>
        <mesh filename="mycobot_pro_600\link1.stl"/>
      </geometry>
      <origin xyz="0 0 0" rpy="0 0 3.1415926"/>
    </collision>
    
    <inertial>
      <mass value="0.0"/>
      <origin xyz="0 0 0"/>
      <inertia ixx="0.1" iyy="0.1" izz="0.1" ixy="0.0" ixz="0.0" iyz="0.0"/>
    </inertial>
  </link>

  <link name="link2">
    <visual>
      <geometry>
        <mesh filename="mycobot_pro_600\link2.stl"/>
      </geometry>
      <material name="light_blue">
        <color rgba="0.678 0.847 0.902 1"/>
      </material>
      <origin xyz="0 0 -0.080" rpy="3.1415926 0 3.1415926"/>
    </visual>
    <collision>
      <geometry>
        <mesh filename="mycobot_pro_600\link2.stl"/>
      </geometry>
      <origin xyz="0 0 -0.080" rpy="3.1415926 0 3.1415926"/>
    </collision>
    
    <inertial>
      <mass value="0.0"/>
      <origin xyz="0 0 0"/>
      <inertia ixx="0.1" iyy="0.1" izz="0.1" ixy="0.0" ixz="0.0" iyz="0.0"/>
    </inertial>
  </link>

  <link name="link3">
    <visual>
      <geometry>
        <mesh filename="mycobot_pro_600\link3.stl"/>
      </geometry>
      <material name="light_blue">
        <color rgba="0.678 0.847 0.902 1"/>
      </material>
      <origin xyz="0 0 -0.0855" rpy="3.1415926 0 3.1415926"/>
    </visual>
    <collision>
      <geometry>
        <mesh filename="mycobot_pro_600\link3.stl"/>
      </geometry>
      <origin xyz="0 0 -0.0855" rpy="3.1415926 0 3.1415926"/>
    </collision>
    
    <inertial>
      <mass value="0.0"/>
      <origin xyz="0 0 0"/>
      <inertia ixx="0.1" iyy="0.1" izz="0.1" ixy="0.0" ixz="0.0" iyz="0.0"/>
    </inertial>
  </link>

  <link name="link4">
    <visual>
      <geometry>
        <mesh filename="mycobot_pro_600\link4.stl"/>
      </geometry>
      <material name="light_blue">
        <color rgba="0.678 0.847 0.902 1"/>
      </material>
      <origin xyz="0 0 0" rpy="0 3.1415926 0"/>
    </visual>
    <collision>
      <geometry>
        <mesh filename="mycobot_pro_600\link4.stl"/>
      </geometry>
      <origin xyz="0 0 0" rpy="0 3.1415926 0"/>
    </collision>
    
    <inertial>
      <mass value="0.0"/>
      <origin xyz="0 0 0"/>
      <inertia ixx="0.1" iyy="0.1" izz="0.1" ixy="0.0" ixz="0.0" iyz="0.0"/>
    </inertial>
  </link>

  <link name="link5">
    <visual>
      <geometry>
        <mesh filename="mycobot_pro_600\link5.stl"/>
      </geometry>
     <material name="light_blue">
        <color rgba="0.678 0.847 0.902 1"/>
      </material>
      <origin xyz="0 0 0" rpy="0 0 1.5707"/>
    </visual>
    <collision>
      <geometry>
        <mesh filename="mycobot_pro_600\link5.stl"/>
      </geometry>
      <origin xyz="0 0 0" rpy="0 0 1.5707"/>
    </collision>
    
    <inertial>
      <mass value="0.0"/>
      <origin xyz="0 0 0"/>
      <inertia ixx="0.1" iyy="0.1" izz="0.1" ixy="0.0" ixz="0.0" iyz="0.0"/>
    </inertial>
  </link>




    <joint name="joint2_to_joint1" type="revolute">
    <axis xyz="0 0 1"/>
    <limit effort = "1000.0" lower = "-3.14" upper = "3.14159" velocity = "1"/>
    <parent link="base"/>
    <child link="link1"/>
    <origin xyz= "0 0 0.19934" rpy = "0 0 0"/>  
  </joint>


  <joint name="joint3_to_joint2" type="revolute">
    <axis xyz="0 0 -1"/>
    <limit effort = "1000.0" lower = "-4.7123" upper = "1.5708" velocity = "1"/>
    <parent link="link1"/>
    <child link="link2"/>
    <origin xyz= "0 0  0" rpy = "1.5708 -1.57080 0"/>  
  </joint>


  <joint name="joint4_to_joint3" type="revolute">
    <axis xyz=" 0 0 -1"/>
    <limit effort = "1000.0" lower = "-2.6179" upper = "2.443" velocity = "1"/>
    <parent link="link2"/>
    <child link="link3"/>
    <origin xyz= "0.25 0 0   " rpy = "0 0 0"/>  
  </joint>

  <joint name="joint5_to_joint4" type="revolute">
    <axis xyz=" 0 0 -1"/>
    <limit effort = "1000.0" lower = "-4.5378" upper = "1.3962" velocity = "1"/>
    <parent link="link3"/>
    <child link="link4"/>
    <origin xyz= "0.25 0  -0.1091" rpy = "0 0 1.57080"/>  
  </joint>

  <joint name="joint6_to_joint5" type="revolute">
    <axis xyz="0 0 1"/>
    <limit effort = "1000.0" lower = "-2.9321" upper = "2.9321" velocity = "1"/>
    <parent link="link4"/>
    <child link="link5"/>
    <origin xyz= "0 -0.108 0" rpy = "1.57080 -1.57080 0"/>  
  </joint>

  



</robot>

